Workbook

Sheet Erklärung

Sheet Rohdaten
A1: ID | B1: Name | C1: Kategorie | D1: Energie, Kilojoule (kJ) | E1: Fett, total (g) | F1: Fettsäuren, gesättigt (g) | G1: Fettsäuren, einfach ungesättigt (g) | H1: Fettsäuren, mehrfach ungesättigt (g) | I1: Kohlenhydrate, verfügbar (g) | J1: Zucker (g) | K1: Stärke (g) | L1: Ballaststoffe (g) | M1: Protein (g) | N1: Vitamin A-Aktivität, RE (µg-RE) | O1: Vitamin A-Aktivität, RAE (µg-RE) | P1: Betacarotin-Aktivität (µg-BCE) | Q1: Betacarotin (µg) | R1: Vitamin B1 (Thiamin) (mg) | S1: Vitamin B2 (Riboflavin) (mg) | T1: Vitamin B6 (Pyridoxin) (mg) | U1: Niacin (mg) | V1: Folat (µg) | W1: Pantothensäure (mg) | X1: Vitamin C (Ascorbinsäure) (mg) | Y1: Vitamin E (α-Tocopherol) (mg) | Z1: Kalium (K) (mg) | AA1: Natrium (Na) (mg) | AB1: Chlorid (Cl) (mg) | AC1: Calcium (Ca) (mg) | AD1: Magnesium (Mg) (mg) | AE1: Phosphor (P) (mg) | AF1: Eisen (Fe) (mg) | AG1: Jod (I) (µg) | AH1: Zink (Zn) (mg) | AI1: Selen (Se) (µg)
A2: 1 | B2: Ananas | C2: Fruechte | D2: 221 | E2: 0.1 | F2: 0 | G2: 0 | H2: 0 | I2: 11.7 | J2: 10.5 | K2: 0 | L2: 1.2 | M2: 0.5 | N2: 8 | O2: 4 | P2: 49 | Q2: 49 | R2: 0.07 | S2: 0.02 | T2: 0.07 | U2: 0.2 | V2: 9.4 | W2: 0.13 | X2: 56.5 | Y2: 0.03 | Z2: 120 | AA2: 1 | AB2: 19 | AC2: 14 | AD2: 11 | AE2: 6 | AF2: 0.2 | AG2: 1.4 | AH2: 0.1 | AI2: 0.1
A3: 2 | B3: Apfel | C3: Fruechte | D3: 222 | E3: 0.3 | F3: 0.1 | G3: 0 | H3: 0.2 | I3: 11.6 | J3: 11.5 | K3: 0.1 | L3: 1.4 | M3: 0.3 | N3: 4 | O3: 2 | P3: 25 | Q3: 23 | R3: 0.01 | S3: 0.01 | T3: 0.04 | U3: 0.08 | V3: 6 | W3: 0.08 | X3: 7.2 | Y3: 0.09 | Z3: 120 | AA3: 1.5 | AB3: 61 | AC3: 5.3 | AD3: 6.5 | AE3: 14 | AF3: 0.1 | AG3: 0.8 | AH3: 0.1 | AI3: 0.5
A4: 3 | B4: Aprikose | C4: Fruechte | D4: 185 | E4: 0.1 | F4: 0 | G4: 0.1 | H4: 0 | I4: 9 | J4: 6.7 | K4: 0 | L4: 1.7 | M4: 0.8 | N4: 384 | O4: 192 | P4: 2305 | Q4: 2243 | R4: 0.02 | S4: 0.02 | T4: 0.06 | U4: 0.38 | V4: 5.6 | W4: 0.18 | X4: 3.6 | Y4: 0.5 | Z4: 260 | AA4: 0 | AB4: 1 | AC4: 15 | AD4: 8.4 | AE4: 22 | AF4: 0.2 | AG4: 0.5 | AH4: 0.1 | AI4: 0.1
A5: 4 | B5: Aubergine | C5: Gemuese | D5: 86 | E5: 0.1 | F5: 0 | G5: 0 | H5: 0.1 | I5: 2.4 | J5: 2.4 | K5: 0 | L5: 2.7 | M5: 1.1 | N5: 8 | O5: 4 | P5: 47 | Q5: 47 | R5: 0.04 | S5: 0.03 | T5: 0.08 | U5: 0.72 | V5: 24.5 | W5: 0.25 | X5: 1.9 | Y5: 0.17 | Z5: 240 | AA5: 2.5 | AB5: 55 | AC5: 12 | AD5: 14 | AE5: 21 | AF5: 0.3 | AG5: 0.1 | AH5: 0.1 | AI5: 3.9
A6: 5 | B6: Banane | C6: Fruechte | D6: 378 | E6: 0.1 | F6: 0 | G6: 0 | H6: 0 | I6: 19.7 | J6: 15.6 | K6: 3.8 | L6: 2.7 | M6: 1.1 | N6: 14 | O6: 7 | P6: 84 | Q6: 54 | R6: 0.05 | S6: 0.03 | T6: 0.25 | U6: 0.6 | V6: 25.6 | W6: 0.23 | X6: 11.9 | Y6: 0 | Z6: 320 | AA6: 0 | AB6: 80 | AC6: 5.1 | AD6: 28 | AE6: 29 | AF6: 0.2 | AG6: 3 | AH6: 0.1 | AI6: 0.5
A7: 6 | B7: Basilikum | C7: Gemuese | D7: 194 | E7: 0.8 | F7: 0.1 | G7: 0 | H7: 0.4 | I7: 5.1 | J7: 5 | K7: 0.1 | L7: 3.1 | M7: 3.1 | N7: 811 | O7: 405 | P7: 4865 | Q7: 4820 | R7: 0.08 | S7: 0.31 | T7: 0.18 | U7: 1.1 | V7: 50 | W7: 0.2 | X7: 26 | Y7: 1 | Z7: 300 | AA7: 9 | AB7: 35 | AC7: 250 | AD7: 11 | AE7: 37 | AF7: 5.5 | AG7: 0.9 | AH7: 0.7 | AI7: 0
A8: 7 | B8: Birne | C8: Fruechte | D8: 227 | E8: 0.3 | F8: 0.1 | G8: 0.1 | H8: 0.1 | I8: 10.9 | J8: 9 | K8: 0 | L8: 2.9 | M8: 0.5 | N8: 2 | O8: 1 | P8: 14 | Q8: 14 | R8: 0.01 | S8: 0.01 | T8: 0.03 | U8: 0.19 | V8: 11.5 | W8: 0.09 | X8: 4.5 | Y8: 0.12 | Z8: 130 | AA8: 1.8 | AB8: 61 | AC8: 6.5 | AD8: 8.2 | AE8: 15 | AF8: 0.1 | AG8: 0.4 | AH8: 0.1 | AI8: 0.5
A9: 8 | B9: Blumenkohl | C9: Gemuese | D9: 109 | E9: 0.7 | F9: 0.2 | G9: 0.1 | H9: 0.3 | I9: 2.1 | J9: 1.7 | K9: 0.2 | L9: 2 | M9: 1.8 | N9: 1 | O9: 1 | P9: 6 | Q9: 6 | R9: 0.04 | S9: 0.09 | T9: 0.15 | U9: 0.26 | V9: 56 | W9: 0.75 | X9: 60.2 | Y9: 0.09 | Z9: 270 | AA9: 6 | AB9: 22 | AC9: 23 | AD9: 9.8 | AE9: 40 | AF9: 0.3 | AG9: 0.7 | AH9: 0.3 | AI9: 1
A10: 9 | B10: Bohne | C10: Gemuese | D10: 134 | E10: 0.2 | F10: 0.1 | G10: 0 | H10: 0.1 | I10: 4.1 | J10: 3.3 | K10: 0.8 | L10: 3 | M10: 1.9 | N10: 57 | O10: 29 | P10: 343 | Q10: 343 | R10: 0.12 | S10: 0.09 | T10: 0.09 | U10: 0.8 | V10: 53.3 | W10: 0.13 | X10: 10.8 | Y10: 0.36 | Z10: 260 | AA10: 3.9 | AB10: 13 | AC10: 52 | AD10: 25 | AE10: 38 | AF10: 1 | AG10: 2.5 | AH10: 0.4 | AI10: 1
A11: 10 | B11: Broccoli | C11: Gemuese | D11: 163 | E11: 0.6 | F11: 0.2 | G11: 0.1 | H11: 0.3 | I11: 3.2 | J11: 1.9 | K11: 0.6 | L11: 3.2 | M11: 3.6 | N11: 92 | O11: 46 | P11: 554 | Q11: 554 | R11: 0.1 | S11: 0.12 | T11: 0.21 | U11: 0.8 | V11: 60.3 | W11: 0.77 | X11: 102.9 | Y11: 1.45 | Z11: 390 | AA11: 12 | AB11: 78 | AC11: 46 | AD11: 21 | AE11: 80 | AF11: 0.9 | AG11: 7.6 | AH11: 0.5 | AI11: 0.8
A12: 11 | B12: Brombeere | C12: Fruechte | D12: 198 | E12: 0.7 | F12: 0.1 | G12: 0.2 | H12: 0.4 | I12: 6.5 | J12: 6.1 | K12: 0 | L12: 5.2 | M12: 1.1 | N12: 19 | O12: 9 | P12: 113 | Q12: 98 | R12: 0.01 | S12: 0.03 | T12: 0.02 | U12: 0.47 | V12: 16.1 | W12: 0.24 | X12: 10.7 | Y12: 0.6 | Z12: 200 | AA12: 1 | AB12: 20 | AC12: 31 | AD12: 20 | AE12: 25 | AF12: 0.4 | AG12: 0.4 | AH12: 0.2 | AI12: 0
A13: 12 | B13: Brunnenkresse | C13: Gemuese | D13: 71 | E13: 0.2 | F13: 0.1 | G13: 0 | H13: 0.1 | I13: 0.3 | J13: 0.3 | K13: 0 | L13: 2.6 | M13: 2.2 | N13: 421 | O13: 211 | P13: 2527 | Q13: 2527 | R13: 0.09 | S13: 0.12 | T13: 0.18 | U13: 0.4 | V13: 173 | W13: 0.18 | X13: 36.3 | Y13: 1.2 | Z13: 300 | AA13: 42 | AB13: 110 | AC13: 160 | AD13: 20 | AE13: 53 | AF13: 1.3 | AG13: 2 | AH13: 0.2 | AI13: 0
... A96: 95 | B96: Zwiebel | C96: Gemuese | D96: 163 | E96: 0.6 | F96: 0.2 | G96: 0 | H96: 0.1 | I96: 6.3 | J96: 4.8 | K96: 0 | L96: 1.9 | M96: 1.1 | N96: 3 | O96: 1 | P96: 16 | Q96: 16 | R96: 0.04 | S96: 0.02 | T96: 0.09 | U96: 0.2 | V96: 29.6 | W96: 0.16 | X96: 5 | Y96: 0.06 | Z96: 140 | AA96: 7.7 | AB96: 23 | AC96: 20 | AD96: 8.5 | AE96: 30 | AF96: 0.2 | AG96: 1.8 | AH96: 0.2 | AI96: 0.6

Sheet Traningsdaten
A1: Traningsdaten für das Perzeptron
A2: Die Trainingsdaten beinhalten für bekannte Lebensmittel eine nachvollziehbare Zuteilung gemäß der Nutzungsform in der Küche (nicht die botanische Definition!).
A3: Obst entspricht dem Zuweisungscode 1 und Gemüse dem Zuweisungscode 0.
A5: Lebensmittelname | B5: Zuweisung | C5: Zuweisungscode | D5: Wert x1 (Zucker in g) | E5: Wert x2 (Magnesium in mg)
A6: Ananas | B6: Obst | C6: 1 | D6: 10.5 | E6: 11
A7: Mandarine | B7: Obst | C7: 1 | D7: 8.6 | E7: 9.3
A8: Mango | B8: Obst | C8: 1 | D8: 12 | E8: 9
A9: Granatapfel | B9: Obst | C9: 1 | D9: 13.3 | E9: 12
A10: Kiwi | B10: Obst | C10: 1 | D10: 8.9 | E10: 13
A11: Weintraube | B11: Obst | C11: 1 | D11: 14.6 | E11: 7.6
A12: Quitte | B12: Obst | C12: 1 | D12: 7.3 | E12: 8.2
A13: Stachelbeere | B13: Obst | C13: 1 | D13: 7.1 | E13: 8
A14: Zwetschge | B14: Obst | C14: 1 | D14: 8.8 | E14: 8
A15: Heidelbeere | B15: Obst | C15: 1 | D15: 10 | E15: 5
A16: Apfel | B16: Obst | C16: 1 | D16: 11.5 | E16: 6.5
A19: Lebensmittelname | B19: Zuweisung | C19: Zuweisungscode | D19: Wert x1 (Zucker in g) | E19: Wert x2 (Magnesium in mg)
A20: Mangold | B20: Gemüse | C20: 0 | D20: 0.5 | E20: 81
A21: Schnittlauch | B21: Gemüse | C21: 0 | D21: 1.9 | E21: 40
A22: Gartensalat | B22: Gemüse | C22: 0 | D22: 1.3 | E22: 11
A23: Lauch | B23: Gemüse | C23: 0 | D23: 3.5 | E23: 8.8
A24: Rote Peperoni | B24: Gemüse | C24: 0 | D24: 5.1 | E24: 12
A25: Grünkohl | B25: Gemüse | C25: 0 | D25: 2.5 | E25: 38
A26: Schwarzwurzel | B26: Gemüse | C26: 0 | D26: 2 | E26: 24
A27: Erbsen | B27: Gemüse | C27: 0 | D27: 5.5 | E27: 34
A28: Zucchini | B28: Gemüse | C28: 0 | D28: 1.9 | E28: 23
A29: Aubergine | B29: Gemüse | C29: 0 | D29: 2.4 | E29: 14
A30: Fenchel | B30: Gemüse | C30: 0 | D30: 0.1 | E30: 12

Sheet Training
A1: DATA-ID | B1: Name | C1: Wertx1 | D1: Wertx2 | E1: Zuweisungscode | F1: Lernrate | G1: Gewicht w1 | H1: Gewicht w2 | I1: Bias | J1: Summe | K1: Vorhersage | L1: Fehler
A2: 0 | B2: DUMMY 1 | C2: 0 | D2: 0 | E2: 1 | F2: =$N$2 -> 0.1 | G2: 0 | H2: 0 | I2: 0 | J2: =C2*G2+D2*H2+I2 -> 0 | K2: =IF(J2>0,1,0) -> 0 | L2: =E2-K2 -> 1 | M2: Lernrate | N2: 0.1
A3: 1 | B3: DUMMY 2 | C3: -1 | D3: 1 | E3: 0 | F3: =$N$2 -> 0.1 | G3: =G2+F3*L2*C3 -> -0.1 | H3: =H2+F3*L2*D3 -> 0.1 | I3: =I2+F3*L2 -> 0.1 | J3: =C3*G3+D3*H3+I3 -> 0.3 | K3: =IF(J3>0,1,0) -> 1 | L3: =E3-K3 -> -1
A4: 2 | B4: Ananas | C4: 10.5 | D4: 11 | E4: 1 | F4: =$N$2 -> 0.1 | G4: =G3+F4*L3*C4 -> -1.15 | H4: =H3+F4*L3*D4 -> -1 | I4: =I3+F4*L3 -> 0 | J4: =C4*G4+D4*H4+I4 -> -23.075 | K4: =IF(J4>0,1,0) -> 0 | L4: =E4-K4 -> 1
A5: 3 | B5: Mandarine | C5: 8.6 | D5: 9.3 | E5: 1 | F5: =$N$2 -> 0.1 | G5: =G4+F5*L4*C5 -> -0.29 | H5: =H4+F5*L4*D5 -> -0.07 | I5: =I4+F5*L4 -> 0.1 | J5: =C5*G5+D5*H5+I5 -> -3.045 | K5: =IF(J5>0,1,0) -> 0 | L5: =E5-K5 -> 1
A6: 4 | B6: Mango | C6: 12 | D6: 9 | E6: 1 | F6: =$N$2 -> 0.1 | G6: =G5+F6*L5*C6 -> 0.91 | H6: =H5+F6*L5*D6 -> 0.83 | I6: =I5+F6*L5 -> 0.2 | J6: =C6*G6+D6*H6+I6 -> 18.59 | K6: =IF(J6>0,1,0) -> 1 | L6: =E6-K6 -> 0
A7: 5 | B7: Granatapfel | C7: 13.3 | D7: 12 | E7: 1 | F7: =$N$2 -> 0.1 | G7: =G6+F7*L6*C7 -> 0.91 | H7: =H6+F7*L6*D7 -> 0.83 | I7: =I6+F7*L6 -> 0.2 | J7: =C7*G7+D7*H7+I7 -> 22.263 | K7: =IF(J7>0,1,0) -> 1 | L7: =E7-K7 -> 0
A8: 6 | B8: Kiwi | C8: 8.9 | D8: 13 | E8: 1 | F8: =$N$2 -> 0.1 | G8: =G7+F8*L7*C8 -> 0.91 | H8: =H7+F8*L7*D8 -> 0.83 | I8: =I7+F8*L7 -> 0.2 | J8: =C8*G8+D8*H8+I8 -> 19.089 | K8: =IF(J8>0,1,0) -> 1 | L8: =E8-K8 -> 0
A9: 7 | B9: Weintraube | C9: 14.6 | D9: 7.6 | E9: 1 | F9: =$N$2 -> 0.1 | G9: =G8+F9*L8*C9 -> 0.91 | H9: =H8+F9*L8*D9 -> 0.83 | I9: =I8+F9*L8 -> 0.2 | J9: =C9*G9+D9*H9+I9 -> 19.794 | K9: =IF(J9>0,1,0) -> 1 | L9: =E9-K9 -> 0
A10: 8 | B10: Quitte | C10: 7.3 | D10: 8.2 | E10: 1 | F10: =$N$2 -> 0.1 | G10: =G9+F10*L9*C10 -> 0.91 | H10: =H9+F10*L9*D10 -> 0.83 | I10: =I9+F10*L9 -> 0.2 | J10: =C10*G10+D10*H10+I10 -> 13.649 | K10: =IF(J10>0,1,0) -> 1 | L10: =E10-K10 -> 0
A11: 9 | B11: Stachelbeere | C11: 7.1 | D11: 8 | E11: 1 | F11: =$N$2 -> 0.1 | G11: =G10+F11*L10*C11 -> 0.91 | H11: =H10+F11*L10*D11 -> 0.83 | I11: =I10+F11*L10 -> 0.2 | J11: =C11*G11+D11*H11+I11 -> 13.301 | K11: =IF(J11>0,1,0) -> 1 | L11: =E11-K11 -> 0
A12: 10 | B12: Zwetschge | C12: 8.8 | D12: 8 | E12: 1 | F12: =$N$2 -> 0.1 | G12: =G11+F12*L11*C12 -> 0.91 | H12: =H11+F12*L11*D12 -> 0.83 | I12: =I11+F12*L11 -> 0.2 | J12: =C12*G12+D12*H12+I12 -> 14.848 | K12: =IF(J12>0,1,0) -> 1 | L12: =E12-K12 -> 0
A13: 11 | B13: Heidelbeere | C13: 10 | D13: 5 | E13: 1 | F13: =$N$2 -> 0.1 | G13: =G12+F13*L12*C13 -> 0.91 | H13: =H12+F13*L12*D13 -> 0.83 | I13: =I12+F13*L12 -> 0.2 | J13: =C13*G13+D13*H13+I13 -> 13.45 | K13: =IF(J13>0,1,0) -> 1 | L13: =E13-K13 -> 0
A14: 12 | B14: Apfel | C14: 11.5 | D14: 6.5 | E14: 1 | F14: =$N$2 -> 0.1 | G14: =G13+F14*L13*C14 -> 0.91 | H14: =H13+F14*L13*D14 -> 0.83 | I14: =I13+F14*L13 -> 0.2 | J14: =C14*G14+D14*H14+I14 -> 16.06 | K14: =IF(J14>0,1,0) -> 1 | L14: =E14-K14 -> 0
... A24: 22 | B24: Aubergine | C24: 2.4 | D24: 14 | E24: 0 | F24: =$N$2 -> 0.1 | G24: =G23+F24*L23*C24 -> 0.72 | H24: =H23+F24*L23*D24 -> -3.17 | I24: =I23+F24*L23 -> 0.1 | J24: =C24*G24+D24*H24+I24 -> -42.552 | K24: =IF(J24>0,1,0) -> 0 | L24: =E24-K24 -> 0
A25: 23 | B25: Fenchel | C25: 0.1 | D25: 12 | E25: 0 | F25: =$N$2 -> 0.1 | G25: =G24+F25*L24*C25 -> 0.72 | H25: =H24+F25*L24*D25 -> -3.17 | I25: =I24+F25*L24 -> 0.1 | J25: =C25*G25+D25*H25+I25 -> -37.868 | K25: =IF(J25>0,1,0) -> 0 | L25: =E25-K25 -> 0 | M25: =SUMPRODUCT(ABS(L4:L25)) -> 3 | N25: Anzahl der Fehler
A26: 2 | B26: Ananas | C26: 10.5 | D26: 11 | E26: 1 | F26: =$N$2 -> 0.1 | G26: =G25+F26*L25*C26 -> 0.72 | H26: =H25+F26*L25*D26 -> -3.17 | I26: =I25+F26*L25 -> 0.1 | J26: =C26*G26+D26*H26+I26 -> -27.21 | K26: =IF(J26>0,1,0) -> 0 | L26: =E26-K26 -> 1
A27: 3 | B27: Mandarine | C27: 8.6 | D27: 9.3 | E27: 1 | F27: =$N$2 -> 0.1 | G27: =G26+F27*L26*C27 -> 1.58 | H27: =H26+F27*L26*D27 -> -2.24 | I27: =I26+F27*L26 -> 0.2 | J27: =C27*G27+D27*H27+I27 -> -7.044 | K27: =IF(J27>0,1,0) -> 0 | L27: =E27-K27 -> 1
A28: 4 | B28: Mango | C28: 12 | D28: 9 | E28: 1 | F28: =$N$2 -> 0.1 | G28: =G27+F28*L27*C28 -> 2.78 | H28: =H27+F28*L27*D28 -> -1.34 | I28: =I27+F28*L27 -> 0.3 | J28: =C28*G28+D28*H28+I28 -> 21.6 | K28: =IF(J28>0,1,0) -> 1 | L28: =E28-K28 -> 0
A29: 5 | B29: Granatapfel | C29: 13.3 | D29: 12 | E29: 1 | F29: =$N$2 -> 0.1 | G29: =G28+F29*L28*C29 -> 2.78 | H29: =H28+F29*L28*D29 -> -1.34 | I29: =I28+F29*L28 -> 0.3 | J29: =C29*G29+D29*H29+I29 -> 21.194 | K29: =IF(J29>0,1,0) -> 1 | L29: =E29-K29 -> 0
A30: 6 | B30: Kiwi | C30: 8.9 | D30: 13 | E30: 1 | F30: =$N$2 -> 0.1 | G30: =G29+F30*L29*C30 -> 2.78 | H30: =H29+F30*L29*D30 -> -1.34 | I30: =I29+F30*L29 -> 0.3 | J30: =C30*G30+D30*H30+I30 -> 7.622 | K30: =IF(J30>0,1,0) -> 1 | L30: =E30-K30 -> 0
A31: 7 | B31: Weintraube | C31: 14.6 | D31: 7.6 | E31: 1 | F31: =$N$2 -> 0.1 | G31: =G30+F31*L30*C31 -> 2.78 | H31: =H30+F31*L30*D31 -> -1.34 | I31: =I30+F31*L30 -> 0.3 | J31: =C31*G31+D31*H31+I31 -> 30.704 | K31: =IF(J31>0,1,0) -> 1 | L31: =E31-K31 -> 0
A32: 8 | B32: Quitte | C32: 7.3 | D32: 8.2 | E32: 1 | F32: =$N$2 -> 0.1 | G32: =G31+F32*L31*C32 -> 2.78 | H32: =H31+F32*L31*D32 -> -1.34 | I32: =I31+F32*L31 -> 0.3 | J32: =C32*G32+D32*H32+I32 -> 9.606 | K32: =IF(J32>0,1,0) -> 1 | L32: =E32-K32 -> 0
A33: 9 | B33: Stachelbeere | C33: 7.1 | D33: 8 | E33: 1 | F33: =$N$2 -> 0.1 | G33: =G32+F33*L32*C33 -> 2.78 | H33: =H32+F33*L32*D33 -> -1.34 | I33: =I32+F33*L32 -> 0.3 | J33: =C33*G33+D33*H33+I33 -> 9.318 | K33: =IF(J33>0,1,0) -> 1 | L33: =E33-K33 -> 0
A34: 10 | B34: Zwetschge | C34: 8.8 | D34: 8 | E34: 1 | F34: =$N$2 -> 0.1 | G34: =G33+F34*L33*C34 -> 2.78 | H34: =H33+F34*L33*D34 -> -1.34 | I34: =I33+F34*L33 -> 0.3 | J34: =C34*G34+D34*H34+I34 -> 14.044 | K34: =IF(J34>0,1,0) -> 1 | L34: =E34-K34 -> 0
A35: 11 | B35: Heidelbeere | C35: 10 | D35: 5 | E35: 1 | F35: =$N$2 -> 0.1 | G35: =G34+F35*L34*C35 -> 2.78 | H35: =H34+F35*L34*D35 -> -1.34 | I35: =I34+F35*L34 -> 0.3 | J35: =C35*G35+D35*H35+I35 -> 21.4 | K35: =IF(J35>0,1,0) -> 1 | L35: =E35-K35 -> 0
A36: 12 | B36: Apfel | C36: 11.5 | D36: 6.5 | E36: 1 | F36: =$N$2 -> 0.1 | G36: =G35+F36*L35*C36 -> 2.78 | H36: =H35+F36*L35*D36 -> -1.34 | I36: =I35+F36*L35 -> 0.3 | J36: =C36*G36+D36*H36+I36 -> 23.56 | K36: =IF(J36>0,1,0) -> 1 | L36: =E36-K36 -> 0
A37: 13 | B37: Mangold | C37: 0.5 | D37: 81 | E37: 0 | F37: =$N$2 -> 0.1 | G37: =G36+F37*L36*C37 -> 2.78 | H37: =H36+F37*L36*D37 -> -1.34 | I37: =I36+F37*L36 -> 0.3 | J37: =C37*G37+D37*H37+I37 -> -106.85 | K37: =IF(J37>0,1,0) -> 0 | L37: =E37-K37 -> 0
... A46: 22 | B46: Aubergine | C46: 2.4 | D46: 14 | E46: 0 | F46: =$N$2 -> 0.1 | G46: =G45+F46*L45*C46 -> 2.78 | H46: =H45+F46*L45*D46 -> -1.34 | I46: =I45+F46*L45 -> 0.3 | J46: =C46*G46+D46*H46+I46 -> -11.788 | K46: =IF(J46>0,1,0) -> 0 | L46: =E46-K46 -> 0
A47: 23 | B47: Fenchel | C47: 0.1 | D47: 12 | E47: 0 | F47: =$N$2 -> 0.1 | G47: =G46+F47*L46*C47 -> 2.78 | H47: =H46+F47*L46*D47 -> -1.34 | I47: =I46+F47*L46 -> 0.3 | J47: =C47*G47+D47*H47+I47 -> -15.502 | K47: =IF(J47>0,1,0) -> 0 | L47: =E47-K47 -> 0 | M47: =SUMPRODUCT(ABS(L26:L47)) -> 2 | N47: Anzahl der Fehler
A48: 2 | B48: Ananas | C48: 10.5 | D48: 11 | E48: 1 | F48: =$N$2 -> 0.1 | G48: =G47+F48*L47*C48 -> 2.78 | H48: =H47+F48*L47*D48 -> -1.34 | I48: =I47+F48*L47 -> 0.3 | J48: =C48*G48+D48*H48+I48 -> 14.75 | K48: =IF(J48>0,1,0) -> 1 | L48: =E48-K48 -> 0
A49: 3 | B49: Mandarine | C49: 8.6 | D49: 9.3 | E49: 1 | F49: =$N$2 -> 0.1 | G49: =G48+F49*L48*C49 -> 2.78 | H49: =H48+F49*L48*D49 -> -1.34 | I49: =I48+F49*L48 -> 0.3 | J49: =C49*G49+D49*H49+I49 -> 11.746 | K49: =IF(J49>0,1,0) -> 1 | L49: =E49-K49 -> 0
A50: 4 | B50: Mango | C50: 12 | D50: 9 | E50: 1 | F50: =$N$2 -> 0.1 | G50: =G49+F50*L49*C50 -> 2.78 | H50: =H49+F50*L49*D50 -> -1.34 | I50: =I49+F50*L49 -> 0.3 | J50: =C50*G50+D50*H50+I50 -> 21.6 | K50: =IF(J50>0,1,0) -> 1 | L50: =E50-K50 -> 0
A51: 5 | B51: Granatapfel | C51: 13.3 | D51: 12 | E51: 1 | F51: =$N$2 -> 0.1 | G51: =G50+F51*L50*C51 -> 2.78 | H51: =H50+F51*L50*D51 -> -1.34 | I51: =I50+F51*L50 -> 0.3 | J51: =C51*G51+D51*H51+I51 -> 21.194 | K51: =IF(J51>0,1,0) -> 1 | L51: =E51-K51 -> 0
A52: 6 | B52: Kiwi | C52: 8.9 | D52: 13 | E52: 1 | F52: =$N$2 -> 0.1 | G52: =G51+F52*L51*C52 -> 2.78 | H52: =H51+F52*L51*D52 -> -1.34 | I52: =I51+F52*L51 -> 0.3 | J52: =C52*G52+D52*H52+I52 -> 7.622 | K52: =IF(J52>0,1,0) -> 1 | L52: =E52-K52 -> 0
A53: 7 | B53: Weintraube | C53: 14.6 | D53: 7.6 | E53: 1 | F53: =$N$2 -> 0.1 | G53: =G52+F53*L52*C53 -> 2.78 | H53: =H52+F53*L52*D53 -> -1.34 | I53: =I52+F53*L52 -> 0.3 | J53: =C53*G53+D53*H53+I53 -> 30.704 | K53: =IF(J53>0,1,0) -> 1 | L53: =E53-K53 -> 0
A54: 8 | B54: Quitte | C54: 7.3 | D54: 8.2 | E54: 1 | F54: =$N$2 -> 0.1 | G54: =G53+F54*L53*C54 -> 2.78 | H54: =H53+F54*L53*D54 -> -1.34 | I54: =I53+F54*L53 -> 0.3 | J54: =C54*G54+D54*H54+I54 -> 9.606 | K54: =IF(J54>0,1,0) -> 1 | L54: =E54-K54 -> 0
A55: 9 | B55: Stachelbeere | C55: 7.1 | D55: 8 | E55: 1 | F55: =$N$2 -> 0.1 | G55: =G54+F55*L54*C55 -> 2.78 | H55: =H54+F55*L54*D55 -> -1.34 | I55: =I54+F55*L54 -> 0.3 | J55: =C55*G55+D55*H55+I55 -> 9.318 | K55: =IF(J55>0,1,0) -> 1 | L55: =E55-K55 -> 0
A56: 10 | B56: Zwetschge | C56: 8.8 | D56: 8 | E56: 1 | F56: =$N$2 -> 0.1 | G56: =G55+F56*L55*C56 -> 2.78 | H56: =H55+F56*L55*D56 -> -1.34 | I56: =I55+F56*L55 -> 0.3 | J56: =C56*G56+D56*H56+I56 -> 14.044 | K56: =IF(J56>0,1,0) -> 1 | L56: =E56-K56 -> 0
A57: 11 | B57: Heidelbeere | C57: 10 | D57: 5 | E57: 1 | F57: =$N$2 -> 0.1 | G57: =G56+F57*L56*C57 -> 2.78 | H57: =H56+F57*L56*D57 -> -1.34 | I57: =I56+F57*L56 -> 0.3 | J57: =C57*G57+D57*H57+I57 -> 21.4 | K57: =IF(J57>0,1,0) -> 1 | L57: =E57-K57 -> 0
...

Sheet Anwendung
A1: Anwendungsdaten für das Perzeptron
A3: Lebensmittelname | B3: Wert x1 (Zucker in g) | C3: Wert x2 (Magnesium in mg) | D3: Summe | E3: Zuweisungscode | F3: Zuweisung
A4: Spinat | B4: 0.1 | C4: 89 | D4: =B4*Training!$G$69 + C4*Training!$H$69 + Training!$I$69 -> -118.682 | E4: =IF(D4>0,1,0) -> 0 | F4: =IF(E4=1,"Obst","Gemüse") -> Gemüse
A5: Heidelbeere | B5: 10 | C5: 5 | D5: =B5*Training!$G$69 + C5*Training!$H$69 + Training!$I$69 -> 21.4 | E5: =IF(D5>0,1,0) -> 1 | F5: =IF(E5=1,"Obst","Gemüse") -> Obst
A6: Preiselbeere | B6: 6.1 | C6: 6 | D6: =B6*Training!$G$69 + C6*Training!$H$69 + Training!$I$69 -> 9.218 | E6: =IF(D6>0,1,0) -> 1 | F6: =IF(E6=1,"Obst","Gemüse") -> Obst
A7: Banane | B7: 15.6 | C7: 28 | D7: =B7*Training!$G$69 + C7*Training!$H$69 + Training!$I$69 -> 6.148 | E7: =IF(D7>0,1,0) -> 1 | F7: =IF(E7=1,"Obst","Gemüse") -> Obst
A8: Broccoli | B8: 1.6 | C8: 21 | D8: =B8*Training!$G$69 + C8*Training!$H$69 + Training!$I$69 -> -23.392 | E8: =IF(D8>0,1,0) -> 0 | F8: =IF(E8=1,"Obst","Gemüse") -> Gemüse
A9: Peperoni | B9: 5.1 | C9: 12 | D9: =B9*Training!$G$69 + C9*Training!$H$69 + Training!$I$69 -> -1.602 | E9: =IF(D9>0,1,0) -> 0 | F9: =IF(E9=1,"Obst","Gemüse") -> Gemüse
A10: Rocula | B10: 2.1 | C10: 1 | D10: =B10*Training!$G$69 + C10*Training!$H$69 + Training!$I$69 -> 4.798 | E10: =IF(D10>0,1,0) -> 1 | F10: =IF(E10=1,"Obst","Gemüse") -> Obst
A11: Holunderbeere | B11: 7.4 | C11: 30 | D11: =B11*Training!$G$69 + C11*Training!$H$69 + Training!$I$69 -> -19.328 | E11: =IF(D11>0,1,0) -> 0 | F11: =IF(E11=1,"Obst","Gemüse") -> Gemüse
D12: =B12*Training!$G$69 + C12*Training!$H$69 + Training!$I$69 -> 0.3 | E12: =IF(D12>0,1,0) -> 1 | F12: =IF(E12=1,"Obst","Gemüse") -> Obst
D13: =B13*Training!$G$69 + C13*Training!$H$69 + Training!$I$69 -> 0.3 | E13: =IF(D13>0,1,0) -> 1 | F13: =IF(E13=1,"Obst","Gemüse") -> Obst
D14: =B14*Training!$G$69 + C14*Training!$H$69 + Training!$I$69 -> 0.3 | E14: =IF(D14>0,1,0) -> 1 | F14: =IF(E14=1,"Obst","Gemüse") -> Obst
